Workbook

Sheet Summary
A1: StockFlow Manual Test Cases
A3: Metric | B3: Value | C3: Notes | E3: Module | F3: Total | G3: High | H3: Medium/Low
A4: Total Test Cases | B4: =COUNTA('Manual Test Cases'!A2:A1000) -> 129 | C4: All manual test cases | E4: Authentication | F4: =COUNTIF('Manual Test Cases'!E:E,E4) -> 14 | G4: =COUNTIFS('Manual Test Cases'!E:E,E4,'Manual Test Cases'!N:N,"High") -> 13 | H4: =COUNTIF('Manual Test Cases'!E:E,E4)-G4 -> 1
A5: High Priority | B5: =COUNTIF('Manual Test Cases'!N2:N1000,"High") -> 82 | C5: Must execute first | E5: Dashboard | F5: =COUNTIF('Manual Test Cases'!E:E,E5) -> 9 | G5: =COUNTIFS('Manual Test Cases'!E:E,E5,'Manual Test Cases'!N:N,"High") -> 1 | H5: =COUNTIF('Manual Test Cases'!E:E,E5)-G5 -> 8
A6: Medium Priority | B6: =COUNTIF('Manual Test Cases'!N2:N1000,"Medium") -> 41 | E6: Inventory Report | F6: =COUNTIF('Manual Test Cases'!E:E,E6) -> 11 | G6: =COUNTIFS('Manual Test Cases'!E:E,E6,'Manual Test Cases'!N:N,"High") -> 6 | H6: =COUNTIF('Manual Test Cases'!E:E,E6)-G6 -> 5
A7: Low Priority | B7: =COUNTIF('Manual Test Cases'!N2:N1000,"Low") -> 6 | E7: Product Management | F7: =COUNTIF('Manual Test Cases'!E:E,E7) -> 30 | G7: =COUNTIFS('Manual Test Cases'!E:E,E7,'Manual Test Cases'!N:N,"High") -> 21 | H7: =COUNTIF('Manual Test Cases'!E:E,E7)-G7 -> 9
A8: Not Run | B8: =COUNTIF('Manual Test Cases'!M2:M1000,"Not Run") -> 129 | C8: Initial status | E8: Role-Based Access | F8: =COUNTIF('Manual Test Cases'!E:E,E8) -> 12 | G8: =COUNTIFS('Manual Test Cases'!E:E,E8,'Manual Test Cases'!N:N,"High") -> 12 | H8: =COUNTIF('Manual Test Cases'!E:E,E8)-G8 -> 0
A9: Pass | B9: =COUNTIF('Manual Test Cases'!M2:M1000,"Pass") -> 0 | E9: Stock-In | F9: =COUNTIF('Manual Test Cases'!E:E,E9) -> 15 | G9: =COUNTIFS('Manual Test Cases'!E:E,E9,'Manual Test Cases'!N:N,"High") -> 12 | H9: =COUNTIF('Manual Test Cases'!E:E,E9)-G9 -> 3
A10: Fail | B10: =COUNTIF('Manual Test Cases'!M2:M1000,"Fail") -> 0 | E10: Stock-Out | F10: =COUNTIF('Manual Test Cases'!E:E,E10) -> 17 | G10: =COUNTIFS('Manual Test Cases'!E:E,E10,'Manual Test Cases'!N:N,"High") -> 16 | H10: =COUNTIF('Manual Test Cases'!E:E,E10)-G10 -> 1
A11: Blocked | B11: =COUNTIF('Manual Test Cases'!M2:M1000,"Blocked") -> 0 | E11: Transaction History | F11: =COUNTIF('Manual Test Cases'!E:E,E11) -> 11 | G11: =COUNTIFS('Manual Test Cases'!E:E,E11,'Manual Test Cases'!N:N,"High") -> 0 | H11: =COUNTIF('Manual Test Cases'!E:E,E11)-G11 -> 11
E12: UI and Validation | F12: =COUNTIF('Manual Test Cases'!E:E,E12) -> 10 | G12: =COUNTIFS('Manual Test Cases'!E:E,E12,'Manual Test Cases'!N:N,"High") -> 1 | H12: =COUNTIF('Manual Test Cases'!E:E,E12)-G12 -> 9

Sheet Manual Test Cases
A1: Test Case ID | B1: Scenario ID | C1: Requirement ID | D1: Business Rule ID | E1: Module | F1: Test Case Title | G1: Test Technique | H1: Preconditions | I1: Test Steps | J1: Test Data | K1: Expected Result | L1: Actual Result | M1: Status | N1: Priority | O1: Test Type | P1: Environment | Q1: Notes
A2: TC-001 | B2: TS-AUTH-001 | C2: FR-AUTH-001 | E2: Authentication | F2: Verify login page is displayed | G2: Use Case Testing | H2: Application is running; user is on Login page | I2: 1. Open frontend URL 2. Observe login page | J2: URL: http://localhost:3000/login | K2: Login page displays username field, password field, Login button, and demo account information. | M2: Not Run | N2: High | O2: UI | P2: Chrome / Local
A3: TC-002 | B3: TS-AUTH-002 | C3: FR-AUTH-001 | E3: Authentication | F3: Verify Admin can login with valid credentials | G3: Equivalence Partitioning | H3: Application is running; user is on Login page | I3: 1. Enter valid admin username 2. Enter valid password 3. Click Login | J3: username=admin password=123456 | K3: Login succeeds. User is redirected to Dashboard. Admin full name and ADMIN role are displayed. | M3: Not Run | N3: High | O3: Positive | P3: Chrome / Local
A4: TC-003 | B4: TS-AUTH-003 | C4: FR-AUTH-001 | E4: Authentication | F4: Verify Staff can login with valid credentials | G4: Equivalence Partitioning | H4: Application is running; user is on Login page | I4: 1. Enter valid staff username 2. Enter valid password 3. Click Login | J4: username=staff password=123456 | K4: Login succeeds. User is redirected to Dashboard. Staff full name and STAFF role are displayed. | M4: Not Run | N4: High | O4: Positive | P4: Chrome / Local
A5: TC-004 | B5: TS-AUTH-004 | C5: FR-AUTH-001 | E5: Authentication | F5: Verify login fails with invalid username | G5: Equivalence Partitioning | H5: Application is running; user is on Login page | I5: 1. Enter invalid username 2. Enter valid password 3. Click Login | J5: username=wrong_user password=123456 | K5: Login fails. Error message is displayed. User remains on Login page. | M5: Not Run | N5: High | O5: Negative | P5: Chrome / Local
A6: TC-005 | B6: TS-AUTH-005 | C6: FR-AUTH-001 | E6: Authentication | F6: Verify login fails with invalid password | G6: Equivalence Partitioning | H6: Application is running; user is on Login page | I6: 1. Enter valid username 2. Enter invalid password 3. Click Login | J6: username=admin password=wrongpass | K6: Login fails. Error message is displayed. User remains on Login page. | M6: Not Run | N6: High | O6: Negative | P6: Chrome / Local
A7: TC-006 | B7: TS-AUTH-006 | C7: FR-AUTH-001 | E7: Authentication | F7: Verify username is required | G7: Validation Testing | H7: Application is running; user is on Login page | I7: 1. Leave username empty 2. Enter password 3. Click Login | J7: username=<empty> password=123456 | K7: Validation message for username required is displayed. Login request is not submitted. | M7: Not Run | N7: High | O7: Validation | P7: Chrome / Local
A8: TC-007 | B8: TS-AUTH-006 | C8: FR-AUTH-001 | E8: Authentication | F8: Verify password is required | G8: Validation Testing | H8: Application is running; user is on Login page | I8: 1. Enter username 2. Leave password empty 3. Click Login | J8: username=admin password=<empty> | K8: Validation message for password required is displayed. Login request is not submitted. | M8: Not Run | N8: High | O8: Validation | P8: Chrome / Local
A9: TC-008 | B9: TS-AUTH-006 | C9: FR-AUTH-001 | E9: Authentication | F9: Verify username and password are both required | G9: Validation Testing | H9: Application is running; user is on Login page | I9: 1. Leave username empty 2. Leave password empty 3. Click Login | J9: username=<empty> password=<empty> | K9: Required validation messages are displayed for both fields. | M9: Not Run | N9: High | O9: Validation | P9: Chrome / Local
A10: TC-009 | B10: TS-AUTH-004 | C10: FR-AUTH-001 | E10: Authentication | F10: Verify login with blank spaces is rejected | G10: Error Guessing | H10: Application is running; user is on Login page | I10: 1. Enter spaces in username 2. Enter password 3. Click Login | J10: username=' ' password=123456 | K10: Login is rejected or validation message is displayed. User is not logged in. | M10: Not Run | N10: Medium | O10: Negative | P10: Chrome / Local
A11: TC-010 | B11: TS-AUTH-004 | C11: FR-AUTH-001 | E11: Authentication | F11: Verify login with SQL injection-like username is rejected | G11: Error Guessing | H11: Application is running; user is on Login page | I11: 1. Enter SQL injection-like text in username 2. Enter password 3. Click Login | J11: username=' OR '1'='1 password=123456 | K11: Login is rejected. System does not crash or bypass authentication. | M11: Not Run | N11: High | O11: Security | P11: Chrome / Local
A12: TC-011 | B12: TS-AUTH-007 | C12: FR-AUTH-002 | E12: Authentication | F12: Verify logged-in user can logout successfully | G12: State Transition Testing | H12: User is logged in as Admin or Staff | I12: 1. Click Logout 2. Confirm user is redirected | J12: admin / 123456 | K12: User is logged out. Auth data is cleared. User is redirected to Login page. | M12: Not Run | N12: High | O12: Functional | P12: Chrome / Local
A13: TC-012 | B13: TS-AUTH-008 | C13: NFR-SEC-001 | D13: BR-014 | E13: Authentication | F13: Verify unauthenticated user cannot access Dashboard | G13: State Transition Testing | H13: User is not logged in | I13: 1. Clear local storage 2. Open /dashboard directly | J13: URL=/dashboard | K13: User is redirected to Login page. | M13: Not Run | N13: High | O13: Security | P13: Chrome / Local
A14: TC-013 | B14: TS-AUTH-008 | C14: NFR-SEC-001 | D14: BR-014 | E14: Authentication | F14: Verify unauthenticated user cannot access Product List | G14: State Transition Testing | H14: User is not logged in | I14: 1. Clear local storage 2. Open /products directly | J14: URL=/products | K14: User is redirected to Login page. | M14: Not Run | N14: High | O14: Security | P14: Chrome / Local
A15: TC-014 | B15: TS-AUTH-008 | C15: NFR-SEC-004 | D15: BR-014 | E15: Authentication | F15: Verify protected API rejects request without token | G15: API / Security Testing | H15: Postman is available; user has no token | I15: 1. Send GET /api/products without Authorization header | J15: No token | K15: API returns Unauthorized response. No product data is returned. | M15: Not Run | N15: High | O15: Security | P15: Chrome / Local | Q15: Also covered in API test cases later.
A16: TC-015 | B16: TS-DASH-001 | C16: FR-DASH-001 | E16: Dashboard | F16: Verify Dashboard page loads after login | G16: Use Case Testing | H16: User is logged in successfully | I16: 1. Login 2. Open Dashboard 3. Observe summary cards | J16: Existing product data | K16: Dashboard page is displayed without error. | M16: Not Run | N16: Medium | O16: Functional | P16: Chrome / Local
A17: TC-016 | B17: TS-DASH-001 | C17: FR-DASH-001 | E17: Dashboard | F17: Verify Total Products card is displayed | G17: Use Case Testing | H17: User is logged in successfully | I17: 1. Login 2. Open Dashboard 3. Observe summary cards | J17: Existing product data | K17: Total Products card shows numeric value. | M17: Not Run | N17: Medium | O17: Functional | P17: Chrome / Local
A18: TC-017 | B18: TS-DASH-001 | C18: FR-DASH-001 | E18: Dashboard | F18: Verify Active Products card is displayed | G18: Use Case Testing | H18: User is logged in successfully | I18: 1. Login 2. Open Dashboard 3. Observe summary cards | J18: Existing product data | K18: Active Products card shows numeric value. | M18: Not Run | N18: Medium | O18: Functional | P18: Chrome / Local
A19: TC-018 | B19: TS-DASH-001 | C19: FR-DASH-001 | E19: Dashboard | F19: Verify Inactive Products card is displayed | G19: Use Case Testing | H19: User is logged in successfully | I19: 1. Login 2. Open Dashboard 3. Observe summary cards | J19: Existing product data | K19: Inactive Products card shows numeric value. | M19: Not Run | N19: Medium | O19: Functional | P19: Chrome / Local
A20: TC-019 | B20: TS-DASH-001 | C20: FR-DASH-001 | E20: Dashboard | F20: Verify Total Stock Quantity card is displayed | G20: Use Case Testing | H20: User is logged in successfully | I20: 1. Login 2. Open Dashboard 3. Observe summary cards | J20: Existing product data | K20: Total Stock Quantity card shows numeric value. | M20: Not Run | N20: Medium | O20: Functional | P20: Chrome / Local
A21: TC-020 | B21: TS-DASH-001 | C21: FR-DASH-001 | E21: Dashboard | F21: Verify Low-Stock Products card is displayed | G21: Use Case Testing | H21: User is logged in successfully | I21: 1. Login 2. Open Dashboard 3. Observe summary cards | J21: Existing product data | K21: Low-Stock Products card shows numeric value. | M21: Not Run | N21: Medium | O21: Functional | P21: Chrome / Local
A22: TC-021 | B22: TS-DASH-001 | C22: FR-DASH-001 | E22: Dashboard | F22: Verify Out-of-Stock Products card is displayed | G22: Use Case Testing | H22: User is logged in successfully | I22: 1. Login 2. Open Dashboard 3. Observe summary cards | J22: Existing product data | K22: Out-of-Stock Products card shows numeric value. | M22: Not Run | N22: Medium | O22: Functional | P22: Chrome / Local
A23: TC-022 | B23: TS-DASH-006 | C23: FR-DASH-001 | E23: Dashboard | F23: Verify Refresh button reloads dashboard data | G23: Use Case Testing | H23: User is logged in successfully | I23: 1. Open Dashboard 2. Click Refresh button 3. Observe loading and refreshed data | J23: Existing product data | K23: Dashboard summary reloads successfully without page error. | M23: Not Run | N23: Low | O23: UI | P23: Chrome / Local
A24: TC-023 | B24: TS-DASH-005 | C24: FR-DASH-001 | D24: BR-011;BR-012 | E24: Dashboard | F24: Verify low-stock and out-of-stock counts follow stock rules | G24: Boundary Value Analysis | H24: Products exist with quantity 0, 1, 10, and 11 | I24: 1. Create/prepare products with boundary quantities 2. Open Dashboard 3. Compare displayed counts | J24: Quantity: 0, 1, 10, 11 | K24: Quantity 0 is counted as out-of-stock. Quantity 1 and 10 are counted as low-stock. Quantity 11 is not low-stock. | M24: Not Run | N24: High | O24: Business Rule | P24: Chrome / Local
A25: TC-024 | B25: TS-PROD-001 | C25: FR-PROD-001 | E25: Product Management | F25: Verify Product List page loads successfully | G25: Use Case Testing | H25: User is logged in successfully | I25: 1. Login 2. Open Product List page | J25: Existing product data | K25: Product List page is displayed with table, search, filters, and pagination. | M25: Not Run | N25: High | O25: Functional | P25: Chrome / Local
A26: TC-025 | B26: TS-PROD-002 | C26: FR-PROD-001 | E26: Product Management | F26: Verify Product List displays product columns correctly | G26: Use Case Testing | H26: User is logged in successfully | I26: 1. Open Product List 2. Observe table columns | J26: Existing product data | K26: Table displays ID, name, category, price, quantity, status, created date, and actions according to role. | M26: Not Run | N26: High | O26: UI | P26: Chrome / Local
A27: TC-026 | B27: TS-PROD-003 | C27: FR-PROD-002 | D27: BR-001;BR-002 | E27: Product Management | F27: Verify Admin can create product with valid data | G27: Equivalence Partitioning | H27: User is logged in as Admin | I27: 1. Open Create Product page 2. Enter valid product data 3. Click Save 4. Open Product List | J27: name=Laptop Dell QA category=Laptop price=15000000 quantity=10 status=ACTIVE | K27: Product is created successfully and appears in Product List. | M27: Not Run | N27: High | O27: Positive | P27: Chrome / Local
A28: TC-027 | B28: TS-PROD-004 | C28: FR-PROD-002 | D28: BR-013 | E28: Product Management | F28: Verify Staff cannot access Create Product page | G28: Role-Based Access Testing | H28: User is logged in as Staff | I28: 1. Open /products/create directly | J28: URL=/products/create | K28: Staff is redirected or access is denied. Create form is not accessible. | M28: Not Run | N28: High | O28: Security | P28: Chrome / Local
A29: TC-028 | B29: TS-PROD-004 | C29: FR-PROD-002 | D29: BR-013 | E29: Product Management | F29: Verify Staff cannot see Add Product button | G29: Role-Based Access Testing | H29: User is logged in as Staff | I29: 1. Open Product List 2. Observe action buttons | J29: Staff account | K29: Add Product button is not displayed. | M29: Not Run | N29: High | O29: Role-Based Access | P29: Chrome / Local
A30: TC-029 | B30: TS-PROD-005 | C30: FR-PROD-002 | D30: BR-001 | E30: Product Management | F30: Verify product name is required | G30: Validation Testing | H30: User is logged in as Admin | I30: 1. Open Create Product page 2. Enter test data 3. Click Save | J30: name=<empty> category=Laptop price=1000000 quantity=1 status=ACTIVE | K30: Product is not created. Product name required validation message is displayed. | M30: Not Run | N30: High | O30: Validation | P30: Chrome / Local
A31: TC-030 | B31: TS-PROD-006 | C31: FR-PROD-002 | D31: BR-001 | E31: Product Management | F31: Verify duplicate product name is rejected | G31: Equivalence Partitioning | H31: User is logged in as Admin | I31: 1. Open Create Product page 2. Enter test data 3. Click Save | J31: name=Existing Product Name category=Laptop price=1000000 quantity=1 status=ACTIVE | K31: Product is not created. Duplicate name error is displayed. | M31: Not Run | N31: High | O31: Validation | P31: Chrome / Local
A32: TC-031 | B32: TS-PROD-007 | C32: FR-PROD-002 | E32: Product Management | F32: Verify category is required | G32: Validation Testing | H32: User is logged in as Admin | I32: 1. Open Create Product page 2. Enter test data 3. Click Save | J32: name=Mouse QA category=<empty> price=1000000 quantity=1 status=ACTIVE | K32: Product is not created. Category required validation message is displayed. | M32: Not Run | N32: High | O32: Validation | P32: Chrome / Local
A33: TC-032 | B33: TS-PROD-008 | C33: FR-PROD-002 | D33: BR-002 | E33: Product Management | F33: Verify price is required | G33: Validation Testing | H33: User is logged in as Admin | I33: 1. Open Create Product page 2. Enter test data 3. Click Save | J33: name=Mouse QA category=Accessory price=<empty> quantity=1 status=ACTIVE | K33: Product is not created. Price required validation message is displayed. | M33: Not Run | N33: High | O33: Validation | P33: Chrome / Local
A34: TC-033 | B34: TS-PROD-008 | C34: FR-PROD-002 | D34: BR-002 | E34: Product Management | F34: Verify price cannot be 0 | G34: Boundary Value Analysis | H34: User is logged in as Admin | I34: 1. Open Create Product page 2. Enter test data 3. Click Save | J34: name=Mouse QA category=Accessory price=0 quantity=1 status=ACTIVE | K34: Product is not created. Price must be greater than 0. | M34: Not Run | N34: High | O34: Validation | P34: Chrome / Local
A35: TC-034 | B35: TS-PROD-008 | C35: FR-PROD-002 | D35: BR-002 | E35: Product Management | F35: Verify price cannot be negative | G35: Boundary Value Analysis | H35: User is logged in as Admin | I35: 1. Open Create Product page 2. Enter test data 3. Click Save | J35: name=Mouse QA category=Accessory price=-1 quantity=1 status=ACTIVE | K35: Product is not created. Price must be greater than 0. | M35: Not Run | N35: High | O35: Validation | P35: Chrome / Local
A36: TC-035 | B36: TS-PROD-009 | C36: FR-PROD-002 | D36: BR-003 | E36: Product Management | F36: Verify initial quantity is required | G36: Validation Testing | H36: User is logged in as Admin | I36: 1. Open Create Product page 2. Enter test data 3. Click Save | J36: name=Mouse QA category=Accessory price=1000000 quantity=<empty> status=ACTIVE | K36: Product is not created. Quantity required validation message is displayed. | M36: Not Run | N36: High | O36: Validation | P36: Chrome / Local
A37: TC-036 | B37: TS-PROD-009 | C37: FR-PROD-002 | D37: BR-003 | E37: Product Management | F37: Verify initial quantity can be 0 | G37: Boundary Value Analysis | H37: User is logged in as Admin | I37: 1. Open Create Product page 2. Enter test data 3. Click Save | J37: name=Mouse QA Zero category=Accessory price=1000000 quantity=0 status=ACTIVE | K37: Product is created successfully with quantity 0. | M37: Not Run | N37: High | O37: Validation | P37: Chrome / Local
A38: TC-037 | B38: TS-PROD-009 | C38: FR-PROD-002 | D38: BR-003 | E38: Product Management | F38: Verify initial quantity cannot be negative | G38: Boundary Value Analysis | H38: User is logged in as Admin | I38: 1. Open Create Product page 2. Enter test data 3. Click Save | J38: name=Mouse QA Negative category=Accessory price=1000000 quantity=-1 status=ACTIVE | K38: Product is not created. Quantity must be greater than or equal to 0. | M38: Not Run | N38: High | O38: Validation | P38: Chrome / Local
A39: TC-038 | B39: TS-PROD-010 | C39: FR-PROD-003 | E39: Product Management | F39: Verify Admin can update product name, category, price, and status | G39: Use Case Testing | H39: User is logged in as Admin | I39: 1. Open Product List 2. Click Edit on an existing product 3. Update editable fields 4. Click Save | J39: Updated name/category/price/status | K39: Product is updated successfully. Product List shows updated information. | M39: Not Run | N39: High | O39: Functional | P39: Chrome / Local
A40: TC-039 | B40: TS-PROD-011 | C40: FR-PROD-003 | D40: BR-004 | E40: Product Management | F40: Verify quantity cannot be edited directly on Product Edit page | G40: Business Rule Testing | H40: User is logged in as Admin | I40: 1. Open Product Edit page 2. Observe quantity field | J40: Existing product | K40: Quantity is displayed as current quantity but is not editable. | M40: Not Run | N40: High | O40: Business Rule | P40: Chrome / Local
...

Sheet Test Data
A1: Data ID | B1: Data Type | C1: Value / Example | D1: Purpose | E1: Related Module | F1: Notes
A2: TD-001 | B2: Admin Account | C2: admin / 123456 | D2: Login and Admin permission tests | E2: Authentication, Role-Based Access | F2: Seed account
A3: TD-002 | B3: Staff Account | C3: staff / 123456 | D3: Login and Staff permission tests | E3: Authentication, Role-Based Access | F3: Seed account
A4: TD-003 | B4: Valid Product | C4: Laptop Dell QA, Laptop, 15000000, 10, ACTIVE | D4: Create product positive case | E4: Product Management | F4: Name should be unique before execution
A5: TD-004 | B5: Duplicate Product | C5: Existing product name | D5: Duplicate name validation | E5: Product Management | F5: Use a product that already exists
A6: TD-005 | B6: Inactive Product | C6: Product status INACTIVE | D6: Inactive product business rule | E6: Stock-In, Stock-Out | F6: Cannot be used in new transactions
A7: TD-006 | B7: Out-of-stock Product | C7: Quantity = 0 | D7: Inventory report and stock-out boundary | E7: Inventory Report, Stock-Out | F7: OUT_OF_STOCK
A8: TD-007 | B8: Low-stock Product Lower Boundary | C8: Quantity = 1 | D8: Low-stock boundary | E8: Dashboard, Inventory Report | F8: LOW_STOCK
A9: TD-008 | B9: Low-stock Product Upper Boundary | C9: Quantity = 10 | D9: Low-stock boundary | E9: Dashboard, Inventory Report | F9: LOW_STOCK
A10: TD-009 | B10: In-stock Product Boundary | C10: Quantity = 11 | D10: In-stock boundary | E10: Dashboard, Inventory Report | F10: IN_STOCK
A11: TD-010 | B11: Invalid Price Zero | C11: 0 | D11: Price boundary validation | E11: Product Management | F11: Rejected
A12: TD-011 | B12: Invalid Price Negative | C12: -1 | D12: Price boundary validation | E12: Product Management | F12: Rejected
... A19: TD-018 | B19: No Result Keyword | C19: NoProductXYZ | D19: Empty state verification | E19: Product Management, History | F19: No matching records

Sheet Techniques
A1: Technique | B1: How it is used in this workbook | C1: Example in StockFlow
A2: Equivalence Partitioning | B2: Split input data into valid and invalid groups. | C2: Valid login vs invalid username/password; active vs inactive product.
A3: Boundary Value Analysis | B3: Test values at and around boundaries. | C3: Price 0/-1; quantity 0/1/10/11; stock-out equal to current stock and greater than current stock.
A4: Decision Table Testing | B4: Combine conditions and actions for business rules. | C4: Delete product: quantity > 0, has history, quantity = 0 and no history.
A5: State Transition Testing | B5: Verify behavior when system changes state. | C5: Login -> logged in -> logout; product ACTIVE -> INACTIVE -> ACTIVE.
A6: Use Case Testing | B6: Verify complete user flows. | C6: Create product; create stock-in; create stock-out; view report.
A7: Error Guessing | B7: Use experience to test likely error-prone cases. | C7: Blank spaces, SQL injection-like input, invalid date range, network/API error.
A8: Role-Based Access Testing | B8: Verify permissions by role. | C8: Admin can create/edit/delete products; Staff cannot access Admin-only actions.
A9: Data Integrity Testing | B9: Verify UI/API actions produce correct database or data changes. | C9: Quantity increases/decreases correctly; failed stock-out does not change quantity.
A10: UI Testing | B10: Verify visual states and messages. | C10: Loading state, empty state, confirmation modal, active sidebar menu.
A11: Validation Testing | B11: Verify required fields and invalid values. | C11: Required username/password/product fields; invalid price and quantity.

Sheet Lists
A1: Module | B1: Priority | C1: Status | D1: Test Type | E1: Technique
A2: Authentication | B2: High | C2: Not Run | D2: Positive | E2: Equivalence Partitioning
A3: Dashboard | B3: Medium | C3: Pass | D3: Negative | E3: Boundary Value Analysis
A4: Product Management | B4: Low | C4: Fail | D4: Functional | E4: Decision Table Testing
A5: Stock-In | C5: Blocked | D5: Validation | E5: State Transition Testing
A6: Stock-Out | C6: Retest | D6: Boundary | E6: Use Case Testing
A7: Transaction History | C7: Skipped | D7: Business Rule | E7: Error Guessing
A8: Inventory Report | D8: Role-Based Access | E8: Role-Based Access Testing
A9: Role-Based Access | D9: Security | E9: Data Integrity Testing
A10: UI and Validation | D10: UI | E10: UI Testing
D11: Data Integrity | E11: Validation Testing
D12: API Authorization | E12: API / Security Testing
E13: API / Negative Testing
E14: Negative Testing
E15: Business Rule Testing
